2024-12-17 23:20:23,276 - WARNING - Not Found: /register/
2024-12-17 23:20:25,605 - WARNING - Not Found: /register/
2024-12-17 23:20:59,288 - INFO - C:\Users\piyus\OneDrive\Desktop\final_noti\notification_project\notification_app\urls.py changed, reloading.
2024-12-17 23:21:03,700 - WARNING - Not Found: /register/
2024-12-17 23:21:15,353 - INFO - C:\Users\piyus\OneDrive\Desktop\final_noti\notification_project\notification_app\urls.py changed, reloading.
2024-12-17 23:22:46,352 - WARNING - Not Found: /register
2024-12-17 23:23:03,124 - INFO - C:\Users\piyus\OneDrive\Desktop\final_noti\notification_project\notification_project\urls.py changed, reloading.
2024-12-17 23:23:06,405 - ERROR - Internal Server Error: /register
Traceback (most recent call last):
  File "C:\Users\piyus\AppData\Local\Programs\Python\Python313\Lib\site-packages\django\core\handlers\exception.py", line 55, in inner
    response = get_response(request)
  File "C:\Users\piyus\AppData\Local\Programs\Python\Python313\Lib\site-packages\django\utils\deprecation.py", line 131, in __call__
    response = self.process_response(request, response)
  File "C:\Users\piyus\AppData\Local\Programs\Python\Python313\Lib\site-packages\django\middleware\common.py", line 108, in process_response
    return self.response_redirect_class(self.get_full_path_with_slash(request))
                                        ~~~~~~~~~~~~~~~~~~~~~~~~~~~~~^^^^^^^^^
  File "C:\Users\piyus\AppData\Local\Programs\Python\Python313\Lib\site-packages\django\middleware\common.py", line 87, in get_full_path_with_slash
    raise RuntimeError(
    ...<9 lines>...
    )
RuntimeError: You called this URL via POST, but the URL doesn't end in a slash and you have APPEND_SLASH set. Django can't redirect to the slash URL while maintaining POST data. Change your form to point to localhost:8000/register/ (note the trailing slash), or set APPEND_SLASH=False in your Django settings.
2024-12-17 23:23:36,527 - INFO - C:\Users\piyus\OneDrive\Desktop\final_noti\notification_project\notification_project\settings.py changed, reloading.
2024-12-17 23:23:48,044 - WARNING - Not Found: /register
2024-12-17 23:24:39,086 - INFO - Notification sent to user dhruv2 (ID: 2): abcd
2024-12-17 23:24:44,213 - INFO - Notification sent to user dhruv (ID: 1): abcd
2024-12-17 23:25:46,582 - INFO - Notification sent to user dhruv (ID: 1): abcd
2024-12-17 23:26:39,095 - INFO - Notification sent to user dhruv (ID: 1): abcd
2024-12-17 23:30:16,223 - INFO - Notification sent to user dhruv (ID: 1): abcd
2024-12-17 23:31:10,563 - INFO - C:\Users\piyus\OneDrive\Desktop\final_noti\notification_project\notification_app\views.py changed, reloading.
2024-12-17 23:31:14,185 - INFO - Notification sent to user dhruv (ID: 1): abcd
2024-12-17 23:31:27,572 - INFO - Notification sent to user dhruv (ID: 1): abcd
2024-12-17 23:31:35,875 - INFO - C:\Users\piyus\OneDrive\Desktop\final_noti\notification_project\notification_app\views.py changed, reloading.
2024-12-17 23:31:38,689 - INFO - Notification sent to user dhruv (ID: 1): abcd
2024-12-17 23:32:35,690 - INFO - C:\Users\piyus\OneDrive\Desktop\final_noti\notification_project\notification_app\views.py changed, reloading.
2024-12-17 23:32:39,444 - INFO - C:\Users\piyus\OneDrive\Desktop\final_noti\notification_project\notification_app\views.py changed, reloading.
2024-12-17 23:32:41,111 - INFO - Notification sent to user dhruv (ID: 1): abcd
2024-12-17 23:33:42,456 - INFO - C:\Users\piyus\OneDrive\Desktop\final_noti\notification_project\notification_app\views.py changed, reloading.
2024-12-17 23:33:45,365 - INFO - Notification sent to user dhruv (ID: 1): abcd
2024-12-17 23:34:00,592 - INFO - C:\Users\piyus\OneDrive\Desktop\final_noti\notification_project\notification_app\views.py changed, reloading.
2024-12-17 23:34:02,659 - INFO - Notification sent to user dhruv (ID: 1): abcd
2024-12-17 23:35:10,404 - WARNING - Bad Request: /register/
2024-12-17 23:35:59,680 - INFO - C:\Users\piyus\OneDrive\Desktop\final_noti\notification_project\notification_app\views.py changed, reloading.
2024-12-17 23:36:34,328 - INFO - C:\Users\piyus\OneDrive\Desktop\final_noti\notification_project\notification_app\views.py changed, reloading.
2024-12-17 23:38:03,568 - INFO - Notification sent to user dhruv2 (ID: 2): sdfd
2024-12-17 23:38:57,008 - INFO - Notification sent to user dhruv (ID: 1): dfef
2024-12-17 23:39:04,234 - INFO - Notification sent to user dhruv2 (ID: 2): dfef
2024-12-17 23:39:45,321 - INFO - Notification sent to user dhruv (ID: 1): csdfq
2024-12-17 23:39:52,003 - INFO - C:\Users\piyus\OneDrive\Desktop\final_noti\notification_project\notification_app\views.py changed, reloading.
2024-12-18 11:14:09,548 - ERROR - Internal Server Error: /notifications/
Traceback (most recent call last):
  File "C:\Users\piyus\AppData\Local\Programs\Python\Python313\Lib\site-packages\django\core\handlers\exception.py", line 55, in inner
    response = get_response(request)
  File "C:\Users\piyus\AppData\Local\Programs\Python\Python313\Lib\site-packages\django\core\handlers\base.py", line 197, in _get_response
    response = wrapped_callback(request, *callback_args, **callback_kwargs)
  File "C:\Users\piyus\AppData\Local\Programs\Python\Python313\Lib\site-packages\django\views\decorators\csrf.py", line 65, in _view_wrapper
    return view_func(request, *args, **kwargs)
  File "C:\Users\piyus\AppData\Local\Programs\Python\Python313\Lib\site-packages\django\views\generic\base.py", line 104, in view
    return self.dispatch(request, *args, **kwargs)
           ~~~~~~~~~~~~~^^^^^^^^^^^^^^^^^^^^^^^^^^
  File "C:\Users\piyus\AppData\Local\Programs\Python\Python313\Lib\site-packages\rest_framework\views.py", line 509, in dispatch
    response = self.handle_exception(exc)
  File "C:\Users\piyus\AppData\Local\Programs\Python\Python313\Lib\site-packages\rest_framework\views.py", line 469, in handle_exception
    self.raise_uncaught_exception(exc)
    ~~~~~~~~~~~~~~~~~~~~~~~~~~~~~^^^^^
  File "C:\Users\piyus\AppData\Local\Programs\Python\Python313\Lib\site-packages\rest_framework\views.py", line 480, in raise_uncaught_exception
    raise exc
  File "C:\Users\piyus\AppData\Local\Programs\Python\Python313\Lib\site-packages\rest_framework\views.py", line 506, in dispatch
    response = handler(request, *args, **kwargs)
  File "C:\Users\piyus\OneDrive\Desktop\final_noti\notification_project\notification_app\views.py", line 72, in get
    print(notifications[0].notification_type)
          ~~~~~~~~~~~~~^^^
  File "C:\Users\piyus\AppData\Local\Programs\Python\Python313\Lib\site-packages\django\db\models\query.py", line 452, in __getitem__
    return qs._result_cache[0]
           ~~~~~~~~~~~~~~~~^^^
IndexError: list index out of range
2024-12-18 11:14:18,271 - WARNING - User with ID None not found. Notification not sent.
2024-12-18 11:14:19,958 - ERROR - Internal Server Error: /notifications/
Traceback (most recent call last):
  File "C:\Users\piyus\AppData\Local\Programs\Python\Python313\Lib\site-packages\django\core\handlers\exception.py", line 55, in inner
    response = get_response(request)
  File "C:\Users\piyus\AppData\Local\Programs\Python\Python313\Lib\site-packages\django\core\handlers\base.py", line 197, in _get_response
    response = wrapped_callback(request, *callback_args, **callback_kwargs)
  File "C:\Users\piyus\AppData\Local\Programs\Python\Python313\Lib\site-packages\django\views\decorators\csrf.py", line 65, in _view_wrapper
    return view_func(request, *args, **kwargs)
  File "C:\Users\piyus\AppData\Local\Programs\Python\Python313\Lib\site-packages\django\views\generic\base.py", line 104, in view
    return self.dispatch(request, *args, **kwargs)
           ~~~~~~~~~~~~~^^^^^^^^^^^^^^^^^^^^^^^^^^
  File "C:\Users\piyus\AppData\Local\Programs\Python\Python313\Lib\site-packages\rest_framework\views.py", line 509, in dispatch
    response = self.handle_exception(exc)
  File "C:\Users\piyus\AppData\Local\Programs\Python\Python313\Lib\site-packages\rest_framework\views.py", line 469, in handle_exception
    self.raise_uncaught_exception(exc)
    ~~~~~~~~~~~~~~~~~~~~~~~~~~~~~^^^^^
  File "C:\Users\piyus\AppData\Local\Programs\Python\Python313\Lib\site-packages\rest_framework\views.py", line 480, in raise_uncaught_exception
    raise exc
  File "C:\Users\piyus\AppData\Local\Programs\Python\Python313\Lib\site-packages\rest_framework\views.py", line 506, in dispatch
    response = handler(request, *args, **kwargs)
  File "C:\Users\piyus\OneDrive\Desktop\final_noti\notification_project\notification_app\views.py", line 72, in get
    print(notifications[0].notification_type)
          ~~~~~~~~~~~~~^^^
  File "C:\Users\piyus\AppData\Local\Programs\Python\Python313\Lib\site-packages\django\db\models\query.py", line 452, in __getitem__
    return qs._result_cache[0]
           ~~~~~~~~~~~~~~~~^^^
IndexError: list index out of range
2024-12-18 11:14:28,763 - ERROR - Internal Server Error: /notifications/
Traceback (most recent call last):
  File "C:\Users\piyus\AppData\Local\Programs\Python\Python313\Lib\site-packages\django\core\handlers\exception.py", line 55, in inner
    response = get_response(request)
  File "C:\Users\piyus\AppData\Local\Programs\Python\Python313\Lib\site-packages\django\core\handlers\base.py", line 197, in _get_response
    response = wrapped_callback(request, *callback_args, **callback_kwargs)
  File "C:\Users\piyus\AppData\Local\Programs\Python\Python313\Lib\site-packages\django\views\decorators\csrf.py", line 65, in _view_wrapper
    return view_func(request, *args, **kwargs)
  File "C:\Users\piyus\AppData\Local\Programs\Python\Python313\Lib\site-packages\django\views\generic\base.py", line 104, in view
    return self.dispatch(request, *args, **kwargs)
           ~~~~~~~~~~~~~^^^^^^^^^^^^^^^^^^^^^^^^^^
  File "C:\Users\piyus\AppData\Local\Programs\Python\Python313\Lib\site-packages\rest_framework\views.py", line 509, in dispatch
    response = self.handle_exception(exc)
  File "C:\Users\piyus\AppData\Local\Programs\Python\Python313\Lib\site-packages\rest_framework\views.py", line 469, in handle_exception
    self.raise_uncaught_exception(exc)
    ~~~~~~~~~~~~~~~~~~~~~~~~~~~~~^^^^^
  File "C:\Users\piyus\AppData\Local\Programs\Python\Python313\Lib\site-packages\rest_framework\views.py", line 480, in raise_uncaught_exception
    raise exc
  File "C:\Users\piyus\AppData\Local\Programs\Python\Python313\Lib\site-packages\rest_framework\views.py", line 506, in dispatch
    response = handler(request, *args, **kwargs)
  File "C:\Users\piyus\OneDrive\Desktop\final_noti\notification_project\notification_app\views.py", line 72, in get
    print(notifications[0].notification_type)
          ~~~~~~~~~~~~~^^^
  File "C:\Users\piyus\AppData\Local\Programs\Python\Python313\Lib\site-packages\django\db\models\query.py", line 452, in __getitem__
    return qs._result_cache[0]
           ~~~~~~~~~~~~~~~~^^^
IndexError: list index out of range
2024-12-18 11:14:37,832 - ERROR - Internal Server Error: /notifications/
Traceback (most recent call last):
  File "C:\Users\piyus\AppData\Local\Programs\Python\Python313\Lib\site-packages\django\core\handlers\exception.py", line 55, in inner
    response = get_response(request)
  File "C:\Users\piyus\AppData\Local\Programs\Python\Python313\Lib\site-packages\django\core\handlers\base.py", line 197, in _get_response
    response = wrapped_callback(request, *callback_args, **callback_kwargs)
  File "C:\Users\piyus\AppData\Local\Programs\Python\Python313\Lib\site-packages\django\views\decorators\csrf.py", line 65, in _view_wrapper
    return view_func(request, *args, **kwargs)
  File "C:\Users\piyus\AppData\Local\Programs\Python\Python313\Lib\site-packages\django\views\generic\base.py", line 104, in view
    return self.dispatch(request, *args, **kwargs)
           ~~~~~~~~~~~~~^^^^^^^^^^^^^^^^^^^^^^^^^^
  File "C:\Users\piyus\AppData\Local\Programs\Python\Python313\Lib\site-packages\rest_framework\views.py", line 509, in dispatch
    response = self.handle_exception(exc)
  File "C:\Users\piyus\AppData\Local\Programs\Python\Python313\Lib\site-packages\rest_framework\views.py", line 469, in handle_exception
    self.raise_uncaught_exception(exc)
    ~~~~~~~~~~~~~~~~~~~~~~~~~~~~~^^^^^
  File "C:\Users\piyus\AppData\Local\Programs\Python\Python313\Lib\site-packages\rest_framework\views.py", line 480, in raise_uncaught_exception
    raise exc
  File "C:\Users\piyus\AppData\Local\Programs\Python\Python313\Lib\site-packages\rest_framework\views.py", line 506, in dispatch
    response = handler(request, *args, **kwargs)
  File "C:\Users\piyus\OneDrive\Desktop\final_noti\notification_project\notification_app\views.py", line 72, in get
    print(notifications[0].notification_type)
          ~~~~~~~~~~~~~^^^
  File "C:\Users\piyus\AppData\Local\Programs\Python\Python313\Lib\site-packages\django\db\models\query.py", line 452, in __getitem__
    return qs._result_cache[0]
           ~~~~~~~~~~~~~~~~^^^
IndexError: list index out of range
2024-12-18 11:14:49,152 - INFO - Notification sent to user dhruv (ID: 1): emergency
2024-12-18 11:14:49,156 - INFO - Notification sent to user dhruv2 (ID: 2): emergency
2024-12-18 11:14:50,791 - ERROR - Internal Server Error: /notifications/
Traceback (most recent call last):
  File "C:\Users\piyus\AppData\Local\Programs\Python\Python313\Lib\site-packages\django\core\handlers\exception.py", line 55, in inner
    response = get_response(request)
  File "C:\Users\piyus\AppData\Local\Programs\Python\Python313\Lib\site-packages\django\core\handlers\base.py", line 197, in _get_response
    response = wrapped_callback(request, *callback_args, **callback_kwargs)
  File "C:\Users\piyus\AppData\Local\Programs\Python\Python313\Lib\site-packages\django\views\decorators\csrf.py", line 65, in _view_wrapper
    return view_func(request, *args, **kwargs)
  File "C:\Users\piyus\AppData\Local\Programs\Python\Python313\Lib\site-packages\django\views\generic\base.py", line 104, in view
    return self.dispatch(request, *args, **kwargs)
           ~~~~~~~~~~~~~^^^^^^^^^^^^^^^^^^^^^^^^^^
  File "C:\Users\piyus\AppData\Local\Programs\Python\Python313\Lib\site-packages\rest_framework\views.py", line 509, in dispatch
    response = self.handle_exception(exc)
  File "C:\Users\piyus\AppData\Local\Programs\Python\Python313\Lib\site-packages\rest_framework\views.py", line 469, in handle_exception
    self.raise_uncaught_exception(exc)
    ~~~~~~~~~~~~~~~~~~~~~~~~~~~~~^^^^^
  File "C:\Users\piyus\AppData\Local\Programs\Python\Python313\Lib\site-packages\rest_framework\views.py", line 480, in raise_uncaught_exception
    raise exc
  File "C:\Users\piyus\AppData\Local\Programs\Python\Python313\Lib\site-packages\rest_framework\views.py", line 506, in dispatch
    response = handler(request, *args, **kwargs)
  File "C:\Users\piyus\OneDrive\Desktop\final_noti\notification_project\notification_app\views.py", line 72, in get
    print(notifications[0].notification_type)
          ~~~~~~~~~~~~~^^^
  File "C:\Users\piyus\AppData\Local\Programs\Python\Python313\Lib\site-packages\django\db\models\query.py", line 452, in __getitem__
    return qs._result_cache[0]
           ~~~~~~~~~~~~~~~~^^^
IndexError: list index out of range
2024-12-18 11:14:53,194 - INFO - Notification sent to user dhruv (ID: 1): emergency
2024-12-18 11:14:53,198 - INFO - Notification sent to user dhruv2 (ID: 2): emergency
2024-12-18 11:14:54,823 - ERROR - Internal Server Error: /notifications/
Traceback (most recent call last):
  File "C:\Users\piyus\AppData\Local\Programs\Python\Python313\Lib\site-packages\django\core\handlers\exception.py", line 55, in inner
    response = get_response(request)
  File "C:\Users\piyus\AppData\Local\Programs\Python\Python313\Lib\site-packages\django\core\handlers\base.py", line 197, in _get_response
    response = wrapped_callback(request, *callback_args, **callback_kwargs)
  File "C:\Users\piyus\AppData\Local\Programs\Python\Python313\Lib\site-packages\django\views\decorators\csrf.py", line 65, in _view_wrapper
    return view_func(request, *args, **kwargs)
  File "C:\Users\piyus\AppData\Local\Programs\Python\Python313\Lib\site-packages\django\views\generic\base.py", line 104, in view
    return self.dispatch(request, *args, **kwargs)
           ~~~~~~~~~~~~~^^^^^^^^^^^^^^^^^^^^^^^^^^
  File "C:\Users\piyus\AppData\Local\Programs\Python\Python313\Lib\site-packages\rest_framework\views.py", line 509, in dispatch
    response = self.handle_exception(exc)
  File "C:\Users\piyus\AppData\Local\Programs\Python\Python313\Lib\site-packages\rest_framework\views.py", line 469, in handle_exception
    self.raise_uncaught_exception(exc)
    ~~~~~~~~~~~~~~~~~~~~~~~~~~~~~^^^^^
  File "C:\Users\piyus\AppData\Local\Programs\Python\Python313\Lib\site-packages\rest_framework\views.py", line 480, in raise_uncaught_exception
    raise exc
  File "C:\Users\piyus\AppData\Local\Programs\Python\Python313\Lib\site-packages\rest_framework\views.py", line 506, in dispatch
    response = handler(request, *args, **kwargs)
  File "C:\Users\piyus\OneDrive\Desktop\final_noti\notification_project\notification_app\views.py", line 72, in get
    print(notifications[0].notification_type)
          ~~~~~~~~~~~~~^^^
  File "C:\Users\piyus\AppData\Local\Programs\Python\Python313\Lib\site-packages\django\db\models\query.py", line 452, in __getitem__
    return qs._result_cache[0]
           ~~~~~~~~~~~~~~~~^^^
IndexError: list index out of range
2024-12-18 11:15:03,111 - ERROR - Internal Server Error: /notifications/
Traceback (most recent call last):
  File "C:\Users\piyus\AppData\Local\Programs\Python\Python313\Lib\site-packages\django\core\handlers\exception.py", line 55, in inner
    response = get_response(request)
  File "C:\Users\piyus\AppData\Local\Programs\Python\Python313\Lib\site-packages\django\core\handlers\base.py", line 197, in _get_response
    response = wrapped_callback(request, *callback_args, **callback_kwargs)
  File "C:\Users\piyus\AppData\Local\Programs\Python\Python313\Lib\site-packages\django\views\decorators\csrf.py", line 65, in _view_wrapper
    return view_func(request, *args, **kwargs)
  File "C:\Users\piyus\AppData\Local\Programs\Python\Python313\Lib\site-packages\django\views\generic\base.py", line 104, in view
    return self.dispatch(request, *args, **kwargs)
           ~~~~~~~~~~~~~^^^^^^^^^^^^^^^^^^^^^^^^^^
  File "C:\Users\piyus\AppData\Local\Programs\Python\Python313\Lib\site-packages\rest_framework\views.py", line 509, in dispatch
    response = self.handle_exception(exc)
  File "C:\Users\piyus\AppData\Local\Programs\Python\Python313\Lib\site-packages\rest_framework\views.py", line 469, in handle_exception
    self.raise_uncaught_exception(exc)
    ~~~~~~~~~~~~~~~~~~~~~~~~~~~~~^^^^^
  File "C:\Users\piyus\AppData\Local\Programs\Python\Python313\Lib\site-packages\rest_framework\views.py", line 480, in raise_uncaught_exception
    raise exc
  File "C:\Users\piyus\AppData\Local\Programs\Python\Python313\Lib\site-packages\rest_framework\views.py", line 506, in dispatch
    response = handler(request, *args, **kwargs)
  File "C:\Users\piyus\OneDrive\Desktop\final_noti\notification_project\notification_app\views.py", line 72, in get
    print(notifications[0].notification_type)
          ~~~~~~~~~~~~~^^^
  File "C:\Users\piyus\AppData\Local\Programs\Python\Python313\Lib\site-packages\django\db\models\query.py", line 452, in __getitem__
    return qs._result_cache[0]
           ~~~~~~~~~~~~~~~~^^^
IndexError: list index out of range
2024-12-18 11:15:05,095 - INFO - Notification sent to user dhruv (ID: 1): emergency
2024-12-18 11:15:05,099 - INFO - Notification sent to user dhruv2 (ID: 2): emergency
2024-12-18 11:15:06,613 - ERROR - Internal Server Error: /notifications/
Traceback (most recent call last):
  File "C:\Users\piyus\AppData\Local\Programs\Python\Python313\Lib\site-packages\django\core\handlers\exception.py", line 55, in inner
    response = get_response(request)
  File "C:\Users\piyus\AppData\Local\Programs\Python\Python313\Lib\site-packages\django\core\handlers\base.py", line 197, in _get_response
    response = wrapped_callback(request, *callback_args, **callback_kwargs)
  File "C:\Users\piyus\AppData\Local\Programs\Python\Python313\Lib\site-packages\django\views\decorators\csrf.py", line 65, in _view_wrapper
    return view_func(request, *args, **kwargs)
  File "C:\Users\piyus\AppData\Local\Programs\Python\Python313\Lib\site-packages\django\views\generic\base.py", line 104, in view
    return self.dispatch(request, *args, **kwargs)
           ~~~~~~~~~~~~~^^^^^^^^^^^^^^^^^^^^^^^^^^
  File "C:\Users\piyus\AppData\Local\Programs\Python\Python313\Lib\site-packages\rest_framework\views.py", line 509, in dispatch
    response = self.handle_exception(exc)
  File "C:\Users\piyus\AppData\Local\Programs\Python\Python313\Lib\site-packages\rest_framework\views.py", line 469, in handle_exception
    self.raise_uncaught_exception(exc)
    ~~~~~~~~~~~~~~~~~~~~~~~~~~~~~^^^^^
  File "C:\Users\piyus\AppData\Local\Programs\Python\Python313\Lib\site-packages\rest_framework\views.py", line 480, in raise_uncaught_exception
    raise exc
  File "C:\Users\piyus\AppData\Local\Programs\Python\Python313\Lib\site-packages\rest_framework\views.py", line 506, in dispatch
    response = handler(request, *args, **kwargs)
  File "C:\Users\piyus\OneDrive\Desktop\final_noti\notification_project\notification_app\views.py", line 72, in get
    print(notifications[0].notification_type)
          ~~~~~~~~~~~~~^^^
  File "C:\Users\piyus\AppData\Local\Programs\Python\Python313\Lib\site-packages\django\db\models\query.py", line 452, in __getitem__
    return qs._result_cache[0]
           ~~~~~~~~~~~~~~~~^^^
IndexError: list index out of range
2024-12-18 11:15:14,283 - INFO - Notification sent to user dhruv (ID: 1): emergency
2024-12-18 11:15:14,287 - INFO - Notification sent to user dhruv2 (ID: 2): emergency
2024-12-18 11:15:15,781 - ERROR - Internal Server Error: /notifications/
Traceback (most recent call last):
  File "C:\Users\piyus\AppData\Local\Programs\Python\Python313\Lib\site-packages\django\core\handlers\exception.py", line 55, in inner
    response = get_response(request)
  File "C:\Users\piyus\AppData\Local\Programs\Python\Python313\Lib\site-packages\django\core\handlers\base.py", line 197, in _get_response
    response = wrapped_callback(request, *callback_args, **callback_kwargs)
  File "C:\Users\piyus\AppData\Local\Programs\Python\Python313\Lib\site-packages\django\views\decorators\csrf.py", line 65, in _view_wrapper
    return view_func(request, *args, **kwargs)
  File "C:\Users\piyus\AppData\Local\Programs\Python\Python313\Lib\site-packages\django\views\generic\base.py", line 104, in view
    return self.dispatch(request, *args, **kwargs)
           ~~~~~~~~~~~~~^^^^^^^^^^^^^^^^^^^^^^^^^^
  File "C:\Users\piyus\AppData\Local\Programs\Python\Python313\Lib\site-packages\rest_framework\views.py", line 509, in dispatch
    response = self.handle_exception(exc)
  File "C:\Users\piyus\AppData\Local\Programs\Python\Python313\Lib\site-packages\rest_framework\views.py", line 469, in handle_exception
    self.raise_uncaught_exception(exc)
    ~~~~~~~~~~~~~~~~~~~~~~~~~~~~~^^^^^
  File "C:\Users\piyus\AppData\Local\Programs\Python\Python313\Lib\site-packages\rest_framework\views.py", line 480, in raise_uncaught_exception
    raise exc
  File "C:\Users\piyus\AppData\Local\Programs\Python\Python313\Lib\site-packages\rest_framework\views.py", line 506, in dispatch
    response = handler(request, *args, **kwargs)
  File "C:\Users\piyus\OneDrive\Desktop\final_noti\notification_project\notification_app\views.py", line 72, in get
    print(notifications[0].notification_type)
          ~~~~~~~~~~~~~^^^
  File "C:\Users\piyus\AppData\Local\Programs\Python\Python313\Lib\site-packages\django\db\models\query.py", line 452, in __getitem__
    return qs._result_cache[0]
           ~~~~~~~~~~~~~~~~^^^
IndexError: list index out of range
2024-12-18 11:15:17,826 - INFO - Notification sent to user dhruv (ID: 1): emergency
2024-12-18 11:15:17,831 - INFO - Notification sent to user dhruv2 (ID: 2): emergency
2024-12-18 11:15:18,964 - ERROR - Internal Server Error: /notifications/
Traceback (most recent call last):
  File "C:\Users\piyus\AppData\Local\Programs\Python\Python313\Lib\site-packages\django\core\handlers\exception.py", line 55, in inner
    response = get_response(request)
  File "C:\Users\piyus\AppData\Local\Programs\Python\Python313\Lib\site-packages\django\core\handlers\base.py", line 197, in _get_response
    response = wrapped_callback(request, *callback_args, **callback_kwargs)
  File "C:\Users\piyus\AppData\Local\Programs\Python\Python313\Lib\site-packages\django\views\decorators\csrf.py", line 65, in _view_wrapper
    return view_func(request, *args, **kwargs)
  File "C:\Users\piyus\AppData\Local\Programs\Python\Python313\Lib\site-packages\django\views\generic\base.py", line 104, in view
    return self.dispatch(request, *args, **kwargs)
           ~~~~~~~~~~~~~^^^^^^^^^^^^^^^^^^^^^^^^^^
  File "C:\Users\piyus\AppData\Local\Programs\Python\Python313\Lib\site-packages\rest_framework\views.py", line 509, in dispatch
    response = self.handle_exception(exc)
  File "C:\Users\piyus\AppData\Local\Programs\Python\Python313\Lib\site-packages\rest_framework\views.py", line 469, in handle_exception
    self.raise_uncaught_exception(exc)
    ~~~~~~~~~~~~~~~~~~~~~~~~~~~~~^^^^^
  File "C:\Users\piyus\AppData\Local\Programs\Python\Python313\Lib\site-packages\rest_framework\views.py", line 480, in raise_uncaught_exception
    raise exc
  File "C:\Users\piyus\AppData\Local\Programs\Python\Python313\Lib\site-packages\rest_framework\views.py", line 506, in dispatch
    response = handler(request, *args, **kwargs)
  File "C:\Users\piyus\OneDrive\Desktop\final_noti\notification_project\notification_app\views.py", line 72, in get
    print(notifications[0].notification_type)
          ~~~~~~~~~~~~~^^^
  File "C:\Users\piyus\AppData\Local\Programs\Python\Python313\Lib\site-packages\django\db\models\query.py", line 452, in __getitem__
    return qs._result_cache[0]
           ~~~~~~~~~~~~~~~~^^^
IndexError: list index out of range
2024-12-18 11:16:04,677 - WARNING - Bad Request: /register/
2024-12-18 11:16:22,471 - ERROR - Internal Server Error: /notifications/
Traceback (most recent call last):
  File "C:\Users\piyus\AppData\Local\Programs\Python\Python313\Lib\site-packages\django\core\handlers\exception.py", line 55, in inner
    response = get_response(request)
  File "C:\Users\piyus\AppData\Local\Programs\Python\Python313\Lib\site-packages\django\core\handlers\base.py", line 197, in _get_response
    response = wrapped_callback(request, *callback_args, **callback_kwargs)
  File "C:\Users\piyus\AppData\Local\Programs\Python\Python313\Lib\site-packages\django\views\decorators\csrf.py", line 65, in _view_wrapper
    return view_func(request, *args, **kwargs)
  File "C:\Users\piyus\AppData\Local\Programs\Python\Python313\Lib\site-packages\django\views\generic\base.py", line 104, in view
    return self.dispatch(request, *args, **kwargs)
           ~~~~~~~~~~~~~^^^^^^^^^^^^^^^^^^^^^^^^^^
  File "C:\Users\piyus\AppData\Local\Programs\Python\Python313\Lib\site-packages\rest_framework\views.py", line 509, in dispatch
    response = self.handle_exception(exc)
  File "C:\Users\piyus\AppData\Local\Programs\Python\Python313\Lib\site-packages\rest_framework\views.py", line 469, in handle_exception
    self.raise_uncaught_exception(exc)
    ~~~~~~~~~~~~~~~~~~~~~~~~~~~~~^^^^^
  File "C:\Users\piyus\AppData\Local\Programs\Python\Python313\Lib\site-packages\rest_framework\views.py", line 480, in raise_uncaught_exception
    raise exc
  File "C:\Users\piyus\AppData\Local\Programs\Python\Python313\Lib\site-packages\rest_framework\views.py", line 506, in dispatch
    response = handler(request, *args, **kwargs)
  File "C:\Users\piyus\OneDrive\Desktop\final_noti\notification_project\notification_app\views.py", line 72, in get
    print(notifications[0].notification_type)
          ~~~~~~~~~~~~~^^^
  File "C:\Users\piyus\AppData\Local\Programs\Python\Python313\Lib\site-packages\django\db\models\query.py", line 452, in __getitem__
    return qs._result_cache[0]
           ~~~~~~~~~~~~~~~~^^^
IndexError: list index out of range
2024-12-18 11:16:28,709 - INFO - Notification sent to user dhruv2 (ID: 2): hello
2024-12-18 11:16:30,302 - ERROR - Internal Server Error: /notifications/
Traceback (most recent call last):
  File "C:\Users\piyus\AppData\Local\Programs\Python\Python313\Lib\site-packages\django\core\handlers\exception.py", line 55, in inner
    response = get_response(request)
  File "C:\Users\piyus\AppData\Local\Programs\Python\Python313\Lib\site-packages\django\core\handlers\base.py", line 197, in _get_response
    response = wrapped_callback(request, *callback_args, **callback_kwargs)
  File "C:\Users\piyus\AppData\Local\Programs\Python\Python313\Lib\site-packages\django\views\decorators\csrf.py", line 65, in _view_wrapper
    return view_func(request, *args, **kwargs)
  File "C:\Users\piyus\AppData\Local\Programs\Python\Python313\Lib\site-packages\django\views\generic\base.py", line 104, in view
    return self.dispatch(request, *args, **kwargs)
           ~~~~~~~~~~~~~^^^^^^^^^^^^^^^^^^^^^^^^^^
  File "C:\Users\piyus\AppData\Local\Programs\Python\Python313\Lib\site-packages\rest_framework\views.py", line 509, in dispatch
    response = self.handle_exception(exc)
  File "C:\Users\piyus\AppData\Local\Programs\Python\Python313\Lib\site-packages\rest_framework\views.py", line 469, in handle_exception
    self.raise_uncaught_exception(exc)
    ~~~~~~~~~~~~~~~~~~~~~~~~~~~~~^^^^^
  File "C:\Users\piyus\AppData\Local\Programs\Python\Python313\Lib\site-packages\rest_framework\views.py", line 480, in raise_uncaught_exception
    raise exc
  File "C:\Users\piyus\AppData\Local\Programs\Python\Python313\Lib\site-packages\rest_framework\views.py", line 506, in dispatch
    response = handler(request, *args, **kwargs)
  File "C:\Users\piyus\OneDrive\Desktop\final_noti\notification_project\notification_app\views.py", line 72, in get
    print(notifications[0].notification_type)
          ~~~~~~~~~~~~~^^^
  File "C:\Users\piyus\AppData\Local\Programs\Python\Python313\Lib\site-packages\django\db\models\query.py", line 452, in __getitem__
    return qs._result_cache[0]
           ~~~~~~~~~~~~~~~~^^^
IndexError: list index out of range
2024-12-18 11:16:39,894 - INFO - Notification sent to user dhruv2 (ID: 2): hello
2024-12-18 11:16:39,899 - INFO - Notification sent to user piyush (ID: 3): hello
2024-12-18 11:16:41,262 - ERROR - Internal Server Error: /notifications/
Traceback (most recent call last):
  File "C:\Users\piyus\AppData\Local\Programs\Python\Python313\Lib\site-packages\django\core\handlers\exception.py", line 55, in inner
    response = get_response(request)
  File "C:\Users\piyus\AppData\Local\Programs\Python\Python313\Lib\site-packages\django\core\handlers\base.py", line 197, in _get_response
    response = wrapped_callback(request, *callback_args, **callback_kwargs)
  File "C:\Users\piyus\AppData\Local\Programs\Python\Python313\Lib\site-packages\django\views\decorators\csrf.py", line 65, in _view_wrapper
    return view_func(request, *args, **kwargs)
  File "C:\Users\piyus\AppData\Local\Programs\Python\Python313\Lib\site-packages\django\views\generic\base.py", line 104, in view
    return self.dispatch(request, *args, **kwargs)
           ~~~~~~~~~~~~~^^^^^^^^^^^^^^^^^^^^^^^^^^
  File "C:\Users\piyus\AppData\Local\Programs\Python\Python313\Lib\site-packages\rest_framework\views.py", line 509, in dispatch
    response = self.handle_exception(exc)
  File "C:\Users\piyus\AppData\Local\Programs\Python\Python313\Lib\site-packages\rest_framework\views.py", line 469, in handle_exception
    self.raise_uncaught_exception(exc)
    ~~~~~~~~~~~~~~~~~~~~~~~~~~~~~^^^^^
  File "C:\Users\piyus\AppData\Local\Programs\Python\Python313\Lib\site-packages\rest_framework\views.py", line 480, in raise_uncaught_exception
    raise exc
  File "C:\Users\piyus\AppData\Local\Programs\Python\Python313\Lib\site-packages\rest_framework\views.py", line 506, in dispatch
    response = handler(request, *args, **kwargs)
  File "C:\Users\piyus\OneDrive\Desktop\final_noti\notification_project\notification_app\views.py", line 72, in get
    print(notifications[0].notification_type)
          ~~~~~~~~~~~~~^^^
  File "C:\Users\piyus\AppData\Local\Programs\Python\Python313\Lib\site-packages\django\db\models\query.py", line 452, in __getitem__
    return qs._result_cache[0]
           ~~~~~~~~~~~~~~~~^^^
IndexError: list index out of range
2024-12-18 11:16:48,900 - ERROR - Internal Server Error: /notifications/
Traceback (most recent call last):
  File "C:\Users\piyus\AppData\Local\Programs\Python\Python313\Lib\site-packages\django\core\handlers\exception.py", line 55, in inner
    response = get_response(request)
  File "C:\Users\piyus\AppData\Local\Programs\Python\Python313\Lib\site-packages\django\core\handlers\base.py", line 197, in _get_response
    response = wrapped_callback(request, *callback_args, **callback_kwargs)
  File "C:\Users\piyus\AppData\Local\Programs\Python\Python313\Lib\site-packages\django\views\decorators\csrf.py", line 65, in _view_wrapper
    return view_func(request, *args, **kwargs)
  File "C:\Users\piyus\AppData\Local\Programs\Python\Python313\Lib\site-packages\django\views\generic\base.py", line 104, in view
    return self.dispatch(request, *args, **kwargs)
           ~~~~~~~~~~~~~^^^^^^^^^^^^^^^^^^^^^^^^^^
  File "C:\Users\piyus\AppData\Local\Programs\Python\Python313\Lib\site-packages\rest_framework\views.py", line 509, in dispatch
    response = self.handle_exception(exc)
  File "C:\Users\piyus\AppData\Local\Programs\Python\Python313\Lib\site-packages\rest_framework\views.py", line 469, in handle_exception
    self.raise_uncaught_exception(exc)
    ~~~~~~~~~~~~~~~~~~~~~~~~~~~~~^^^^^
  File "C:\Users\piyus\AppData\Local\Programs\Python\Python313\Lib\site-packages\rest_framework\views.py", line 480, in raise_uncaught_exception
    raise exc
  File "C:\Users\piyus\AppData\Local\Programs\Python\Python313\Lib\site-packages\rest_framework\views.py", line 506, in dispatch
    response = handler(request, *args, **kwargs)
  File "C:\Users\piyus\OneDrive\Desktop\final_noti\notification_project\notification_app\views.py", line 72, in get
    print(notifications[0].notification_type)
          ~~~~~~~~~~~~~^^^
  File "C:\Users\piyus\AppData\Local\Programs\Python\Python313\Lib\site-packages\django\db\models\query.py", line 452, in __getitem__
    return qs._result_cache[0]
           ~~~~~~~~~~~~~~~~^^^
IndexError: list index out of range
2024-12-18 11:22:33,415 - WARNING - Bad Request: /register/
2024-12-18 11:22:37,113 - WARNING - Bad Request: /register/
2024-12-18 11:22:40,545 - WARNING - Bad Request: /register/
2024-12-18 11:23:02,315 - ERROR - Internal Server Error: /notifications/
Traceback (most recent call last):
  File "C:\Users\piyus\AppData\Local\Programs\Python\Python313\Lib\site-packages\django\core\handlers\exception.py", line 55, in inner
    response = get_response(request)
  File "C:\Users\piyus\AppData\Local\Programs\Python\Python313\Lib\site-packages\django\core\handlers\base.py", line 197, in _get_response
    response = wrapped_callback(request, *callback_args, **callback_kwargs)
  File "C:\Users\piyus\AppData\Local\Programs\Python\Python313\Lib\site-packages\django\views\decorators\csrf.py", line 65, in _view_wrapper
    return view_func(request, *args, **kwargs)
  File "C:\Users\piyus\AppData\Local\Programs\Python\Python313\Lib\site-packages\django\views\generic\base.py", line 104, in view
    return self.dispatch(request, *args, **kwargs)
           ~~~~~~~~~~~~~^^^^^^^^^^^^^^^^^^^^^^^^^^
  File "C:\Users\piyus\AppData\Local\Programs\Python\Python313\Lib\site-packages\rest_framework\views.py", line 509, in dispatch
    response = self.handle_exception(exc)
  File "C:\Users\piyus\AppData\Local\Programs\Python\Python313\Lib\site-packages\rest_framework\views.py", line 469, in handle_exception
    self.raise_uncaught_exception(exc)
    ~~~~~~~~~~~~~~~~~~~~~~~~~~~~~^^^^^
  File "C:\Users\piyus\AppData\Local\Programs\Python\Python313\Lib\site-packages\rest_framework\views.py", line 480, in raise_uncaught_exception
    raise exc
  File "C:\Users\piyus\AppData\Local\Programs\Python\Python313\Lib\site-packages\rest_framework\views.py", line 506, in dispatch
    response = handler(request, *args, **kwargs)
  File "C:\Users\piyus\OneDrive\Desktop\final_noti\notification_project\notification_app\views.py", line 72, in get
    print(notifications[0].notification_type)
          ~~~~~~~~~~~~~^^^
  File "C:\Users\piyus\AppData\Local\Programs\Python\Python313\Lib\site-packages\django\db\models\query.py", line 452, in __getitem__
    return qs._result_cache[0]
           ~~~~~~~~~~~~~~~~^^^
IndexError: list index out of range
2024-12-18 11:23:07,938 - INFO - Notification sent to user dhruv2 (ID: 2): hello
2024-12-18 11:23:09,667 - ERROR - Internal Server Error: /notifications/
Traceback (most recent call last):
  File "C:\Users\piyus\AppData\Local\Programs\Python\Python313\Lib\site-packages\django\core\handlers\exception.py", line 55, in inner
    response = get_response(request)
  File "C:\Users\piyus\AppData\Local\Programs\Python\Python313\Lib\site-packages\django\core\handlers\base.py", line 197, in _get_response
    response = wrapped_callback(request, *callback_args, **callback_kwargs)
  File "C:\Users\piyus\AppData\Local\Programs\Python\Python313\Lib\site-packages\django\views\decorators\csrf.py", line 65, in _view_wrapper
    return view_func(request, *args, **kwargs)
  File "C:\Users\piyus\AppData\Local\Programs\Python\Python313\Lib\site-packages\django\views\generic\base.py", line 104, in view
    return self.dispatch(request, *args, **kwargs)
           ~~~~~~~~~~~~~^^^^^^^^^^^^^^^^^^^^^^^^^^
  File "C:\Users\piyus\AppData\Local\Programs\Python\Python313\Lib\site-packages\rest_framework\views.py", line 509, in dispatch
    response = self.handle_exception(exc)
  File "C:\Users\piyus\AppData\Local\Programs\Python\Python313\Lib\site-packages\rest_framework\views.py", line 469, in handle_exception
    self.raise_uncaught_exception(exc)
    ~~~~~~~~~~~~~~~~~~~~~~~~~~~~~^^^^^
  File "C:\Users\piyus\AppData\Local\Programs\Python\Python313\Lib\site-packages\rest_framework\views.py", line 480, in raise_uncaught_exception
    raise exc
  File "C:\Users\piyus\AppData\Local\Programs\Python\Python313\Lib\site-packages\rest_framework\views.py", line 506, in dispatch
    response = handler(request, *args, **kwargs)
  File "C:\Users\piyus\OneDrive\Desktop\final_noti\notification_project\notification_app\views.py", line 72, in get
    print(notifications[0].notification_type)
          ~~~~~~~~~~~~~^^^
  File "C:\Users\piyus\AppData\Local\Programs\Python\Python313\Lib\site-packages\django\db\models\query.py", line 452, in __getitem__
    return qs._result_cache[0]
           ~~~~~~~~~~~~~~~~^^^
IndexError: list index out of range
2024-12-18 11:23:13,660 - INFO - Notification sent to user dhruv (ID: 1): hello
2024-12-18 11:23:13,664 - INFO - Notification sent to user dhruv2 (ID: 2): hello
2024-12-18 11:23:14,974 - ERROR - Internal Server Error: /notifications/
Traceback (most recent call last):
  File "C:\Users\piyus\AppData\Local\Programs\Python\Python313\Lib\site-packages\django\core\handlers\exception.py", line 55, in inner
    response = get_response(request)
  File "C:\Users\piyus\AppData\Local\Programs\Python\Python313\Lib\site-packages\django\core\handlers\base.py", line 197, in _get_response
    response = wrapped_callback(request, *callback_args, **callback_kwargs)
  File "C:\Users\piyus\AppData\Local\Programs\Python\Python313\Lib\site-packages\django\views\decorators\csrf.py", line 65, in _view_wrapper
    return view_func(request, *args, **kwargs)
  File "C:\Users\piyus\AppData\Local\Programs\Python\Python313\Lib\site-packages\django\views\generic\base.py", line 104, in view
    return self.dispatch(request, *args, **kwargs)
           ~~~~~~~~~~~~~^^^^^^^^^^^^^^^^^^^^^^^^^^
  File "C:\Users\piyus\AppData\Local\Programs\Python\Python313\Lib\site-packages\rest_framework\views.py", line 509, in dispatch
    response = self.handle_exception(exc)
  File "C:\Users\piyus\AppData\Local\Programs\Python\Python313\Lib\site-packages\rest_framework\views.py", line 469, in handle_exception
    self.raise_uncaught_exception(exc)
    ~~~~~~~~~~~~~~~~~~~~~~~~~~~~~^^^^^
  File "C:\Users\piyus\AppData\Local\Programs\Python\Python313\Lib\site-packages\rest_framework\views.py", line 480, in raise_uncaught_exception
    raise exc
  File "C:\Users\piyus\AppData\Local\Programs\Python\Python313\Lib\site-packages\rest_framework\views.py", line 506, in dispatch
    response = handler(request, *args, **kwargs)
  File "C:\Users\piyus\OneDrive\Desktop\final_noti\notification_project\notification_app\views.py", line 72, in get
    print(notifications[0].notification_type)
          ~~~~~~~~~~~~~^^^
  File "C:\Users\piyus\AppData\Local\Programs\Python\Python313\Lib\site-packages\django\db\models\query.py", line 452, in __getitem__
    return qs._result_cache[0]
           ~~~~~~~~~~~~~~~~^^^
IndexError: list index out of range
2024-12-18 11:31:23,418 - INFO - C:\Users\piyus\OneDrive\Desktop\final_noti\notification_project\notification_app\views.py changed, reloading.
2024-12-18 11:31:23,493 - INFO - C:\Users\piyus\OneDrive\Desktop\final_noti\notification_project\notification_app\views.py changed, reloading.
2024-12-18 11:32:03,957 - INFO - C:\Users\piyus\OneDrive\Desktop\final_noti\notification_project\notification_app\urls.py changed, reloading.
2024-12-18 11:32:03,970 - INFO - C:\Users\piyus\OneDrive\Desktop\final_noti\notification_project\notification_app\urls.py changed, reloading.
2024-12-18 11:32:05,733 - INFO - C:\Users\piyus\OneDrive\Desktop\final_noti\notification_project\notification_app\views.py changed, reloading.
2024-12-18 11:32:05,752 - INFO - C:\Users\piyus\OneDrive\Desktop\final_noti\notification_project\notification_app\views.py changed, reloading.
2024-12-18 11:32:23,570 - WARNING - Unauthorized: /delete/
2024-12-18 11:33:38,248 - INFO - C:\Users\piyus\OneDrive\Desktop\final_noti\notification_project\notification_app\views.py changed, reloading.
2024-12-18 11:33:38,373 - INFO - C:\Users\piyus\OneDrive\Desktop\final_noti\notification_project\notification_app\views.py changed, reloading.
2024-12-18 11:33:40,767 - WARNING - Method Not Allowed: /delete/
2024-12-18 11:34:04,038 - WARNING - Method Not Allowed: /delete/
2024-12-18 11:34:08,421 - INFO - Deleted 31 notifications.
2024-12-18 11:34:08,422 - INFO - Deleted 7 users.
2024-12-18 11:34:50,767 - WARNING - Unauthorized: /login/
2024-12-18 11:34:59,210 - ERROR - Internal Server Error: /notifications/
Traceback (most recent call last):
  File "C:\Users\piyus\AppData\Local\Programs\Python\Python313\Lib\site-packages\django\core\handlers\exception.py", line 55, in inner
    response = get_response(request)
  File "C:\Users\piyus\AppData\Local\Programs\Python\Python313\Lib\site-packages\django\core\handlers\base.py", line 197, in _get_response
    response = wrapped_callback(request, *callback_args, **callback_kwargs)
  File "C:\Users\piyus\AppData\Local\Programs\Python\Python313\Lib\site-packages\django\views\decorators\csrf.py", line 65, in _view_wrapper
    return view_func(request, *args, **kwargs)
  File "C:\Users\piyus\AppData\Local\Programs\Python\Python313\Lib\site-packages\django\views\generic\base.py", line 104, in view
    return self.dispatch(request, *args, **kwargs)
           ~~~~~~~~~~~~~^^^^^^^^^^^^^^^^^^^^^^^^^^
  File "C:\Users\piyus\AppData\Local\Programs\Python\Python313\Lib\site-packages\rest_framework\views.py", line 509, in dispatch
    response = self.handle_exception(exc)
  File "C:\Users\piyus\AppData\Local\Programs\Python\Python313\Lib\site-packages\rest_framework\views.py", line 469, in handle_exception
    self.raise_uncaught_exception(exc)
    ~~~~~~~~~~~~~~~~~~~~~~~~~~~~~^^^^^
  File "C:\Users\piyus\AppData\Local\Programs\Python\Python313\Lib\site-packages\rest_framework\views.py", line 480, in raise_uncaught_exception
    raise exc
  File "C:\Users\piyus\AppData\Local\Programs\Python\Python313\Lib\site-packages\rest_framework\views.py", line 506, in dispatch
    response = handler(request, *args, **kwargs)
  File "C:\Users\piyus\OneDrive\Desktop\final_noti\notification_project\notification_app\views.py", line 72, in get
    print(notifications[0].notification_type)
          ~~~~~~~~~~~~~^^^
  File "C:\Users\piyus\AppData\Local\Programs\Python\Python313\Lib\site-packages\django\db\models\query.py", line 452, in __getitem__
    return qs._result_cache[0]
           ~~~~~~~~~~~~~~~~^^^
IndexError: list index out of range
2024-12-18 11:35:12,124 - WARNING - User with ID 2 not found. Notification not sent.
2024-12-18 11:35:12,124 - WARNING - User with ID 3 not found. Notification not sent.
2024-12-18 11:35:15,182 - ERROR - Internal Server Error: /notifications/
Traceback (most recent call last):
  File "C:\Users\piyus\AppData\Local\Programs\Python\Python313\Lib\site-packages\django\core\handlers\exception.py", line 55, in inner
    response = get_response(request)
  File "C:\Users\piyus\AppData\Local\Programs\Python\Python313\Lib\site-packages\django\core\handlers\base.py", line 197, in _get_response
    response = wrapped_callback(request, *callback_args, **callback_kwargs)
  File "C:\Users\piyus\AppData\Local\Programs\Python\Python313\Lib\site-packages\django\views\decorators\csrf.py", line 65, in _view_wrapper
    return view_func(request, *args, **kwargs)
  File "C:\Users\piyus\AppData\Local\Programs\Python\Python313\Lib\site-packages\django\views\generic\base.py", line 104, in view
    return self.dispatch(request, *args, **kwargs)
           ~~~~~~~~~~~~~^^^^^^^^^^^^^^^^^^^^^^^^^^
  File "C:\Users\piyus\AppData\Local\Programs\Python\Python313\Lib\site-packages\rest_framework\views.py", line 509, in dispatch
    response = self.handle_exception(exc)
  File "C:\Users\piyus\AppData\Local\Programs\Python\Python313\Lib\site-packages\rest_framework\views.py", line 469, in handle_exception
    self.raise_uncaught_exception(exc)
    ~~~~~~~~~~~~~~~~~~~~~~~~~~~~~^^^^^
  File "C:\Users\piyus\AppData\Local\Programs\Python\Python313\Lib\site-packages\rest_framework\views.py", line 480, in raise_uncaught_exception
    raise exc
  File "C:\Users\piyus\AppData\Local\Programs\Python\Python313\Lib\site-packages\rest_framework\views.py", line 506, in dispatch
    response = handler(request, *args, **kwargs)
  File "C:\Users\piyus\OneDrive\Desktop\final_noti\notification_project\notification_app\views.py", line 72, in get
    print(notifications[0].notification_type)
          ~~~~~~~~~~~~~^^^
  File "C:\Users\piyus\AppData\Local\Programs\Python\Python313\Lib\site-packages\django\db\models\query.py", line 452, in __getitem__
    return qs._result_cache[0]
           ~~~~~~~~~~~~~~~~^^^
IndexError: list index out of range
2024-12-18 11:35:21,848 - ERROR - Internal Server Error: /notifications/
Traceback (most recent call last):
  File "C:\Users\piyus\AppData\Local\Programs\Python\Python313\Lib\site-packages\django\core\handlers\exception.py", line 55, in inner
    response = get_response(request)
  File "C:\Users\piyus\AppData\Local\Programs\Python\Python313\Lib\site-packages\django\core\handlers\base.py", line 197, in _get_response
    response = wrapped_callback(request, *callback_args, **callback_kwargs)
  File "C:\Users\piyus\AppData\Local\Programs\Python\Python313\Lib\site-packages\django\views\decorators\csrf.py", line 65, in _view_wrapper
    return view_func(request, *args, **kwargs)
  File "C:\Users\piyus\AppData\Local\Programs\Python\Python313\Lib\site-packages\django\views\generic\base.py", line 104, in view
    return self.dispatch(request, *args, **kwargs)
           ~~~~~~~~~~~~~^^^^^^^^^^^^^^^^^^^^^^^^^^
  File "C:\Users\piyus\AppData\Local\Programs\Python\Python313\Lib\site-packages\rest_framework\views.py", line 509, in dispatch
    response = self.handle_exception(exc)
  File "C:\Users\piyus\AppData\Local\Programs\Python\Python313\Lib\site-packages\rest_framework\views.py", line 469, in handle_exception
    self.raise_uncaught_exception(exc)
    ~~~~~~~~~~~~~~~~~~~~~~~~~~~~~^^^^^
  File "C:\Users\piyus\AppData\Local\Programs\Python\Python313\Lib\site-packages\rest_framework\views.py", line 480, in raise_uncaught_exception
    raise exc
  File "C:\Users\piyus\AppData\Local\Programs\Python\Python313\Lib\site-packages\rest_framework\views.py", line 506, in dispatch
    response = handler(request, *args, **kwargs)
  File "C:\Users\piyus\OneDrive\Desktop\final_noti\notification_project\notification_app\views.py", line 72, in get
    print(notifications[0].notification_type)
          ~~~~~~~~~~~~~^^^
  File "C:\Users\piyus\AppData\Local\Programs\Python\Python313\Lib\site-packages\django\db\models\query.py", line 452, in __getitem__
    return qs._result_cache[0]
           ~~~~~~~~~~~~~~~~^^^
IndexError: list index out of range
2024-12-18 11:35:38,272 - ERROR - Internal Server Error: /notifications/
Traceback (most recent call last):
  File "C:\Users\piyus\AppData\Local\Programs\Python\Python313\Lib\site-packages\django\core\handlers\exception.py", line 55, in inner
    response = get_response(request)
  File "C:\Users\piyus\AppData\Local\Programs\Python\Python313\Lib\site-packages\django\core\handlers\base.py", line 197, in _get_response
    response = wrapped_callback(request, *callback_args, **callback_kwargs)
  File "C:\Users\piyus\AppData\Local\Programs\Python\Python313\Lib\site-packages\django\views\decorators\csrf.py", line 65, in _view_wrapper
    return view_func(request, *args, **kwargs)
  File "C:\Users\piyus\AppData\Local\Programs\Python\Python313\Lib\site-packages\django\views\generic\base.py", line 104, in view
    return self.dispatch(request, *args, **kwargs)
           ~~~~~~~~~~~~~^^^^^^^^^^^^^^^^^^^^^^^^^^
  File "C:\Users\piyus\AppData\Local\Programs\Python\Python313\Lib\site-packages\rest_framework\views.py", line 509, in dispatch
    response = self.handle_exception(exc)
  File "C:\Users\piyus\AppData\Local\Programs\Python\Python313\Lib\site-packages\rest_framework\views.py", line 469, in handle_exception
    self.raise_uncaught_exception(exc)
    ~~~~~~~~~~~~~~~~~~~~~~~~~~~~~^^^^^
  File "C:\Users\piyus\AppData\Local\Programs\Python\Python313\Lib\site-packages\rest_framework\views.py", line 480, in raise_uncaught_exception
    raise exc
  File "C:\Users\piyus\AppData\Local\Programs\Python\Python313\Lib\site-packages\rest_framework\views.py", line 506, in dispatch
    response = handler(request, *args, **kwargs)
  File "C:\Users\piyus\OneDrive\Desktop\final_noti\notification_project\notification_app\views.py", line 72, in get
    print(notifications[0].notification_type)
          ~~~~~~~~~~~~~^^^
  File "C:\Users\piyus\AppData\Local\Programs\Python\Python313\Lib\site-packages\django\db\models\query.py", line 452, in __getitem__
    return qs._result_cache[0]
           ~~~~~~~~~~~~~~~~^^^
IndexError: list index out of range
2024-12-18 11:37:06,021 - WARNING - User with ID 2 not found. Notification not sent.
2024-12-18 11:37:07,632 - ERROR - Internal Server Error: /notifications/
Traceback (most recent call last):
  File "C:\Users\piyus\AppData\Local\Programs\Python\Python313\Lib\site-packages\django\core\handlers\exception.py", line 55, in inner
    response = get_response(request)
  File "C:\Users\piyus\AppData\Local\Programs\Python\Python313\Lib\site-packages\django\core\handlers\base.py", line 197, in _get_response
    response = wrapped_callback(request, *callback_args, **callback_kwargs)
  File "C:\Users\piyus\AppData\Local\Programs\Python\Python313\Lib\site-packages\django\views\decorators\csrf.py", line 65, in _view_wrapper
    return view_func(request, *args, **kwargs)
  File "C:\Users\piyus\AppData\Local\Programs\Python\Python313\Lib\site-packages\django\views\generic\base.py", line 104, in view
    return self.dispatch(request, *args, **kwargs)
           ~~~~~~~~~~~~~^^^^^^^^^^^^^^^^^^^^^^^^^^
  File "C:\Users\piyus\AppData\Local\Programs\Python\Python313\Lib\site-packages\rest_framework\views.py", line 509, in dispatch
    response = self.handle_exception(exc)
  File "C:\Users\piyus\AppData\Local\Programs\Python\Python313\Lib\site-packages\rest_framework\views.py", line 469, in handle_exception
    self.raise_uncaught_exception(exc)
    ~~~~~~~~~~~~~~~~~~~~~~~~~~~~~^^^^^
  File "C:\Users\piyus\AppData\Local\Programs\Python\Python313\Lib\site-packages\rest_framework\views.py", line 480, in raise_uncaught_exception
    raise exc
  File "C:\Users\piyus\AppData\Local\Programs\Python\Python313\Lib\site-packages\rest_framework\views.py", line 506, in dispatch
    response = handler(request, *args, **kwargs)
  File "C:\Users\piyus\OneDrive\Desktop\final_noti\notification_project\notification_app\views.py", line 72, in get
    print(notifications[0].notification_type)
          ~~~~~~~~~~~~~^^^
  File "C:\Users\piyus\AppData\Local\Programs\Python\Python313\Lib\site-packages\django\db\models\query.py", line 452, in __getitem__
    return qs._result_cache[0]
           ~~~~~~~~~~~~~~~~^^^
IndexError: list index out of range
2024-12-18 11:37:14,689 - ERROR - Internal Server Error: /notifications/
Traceback (most recent call last):
  File "C:\Users\piyus\AppData\Local\Programs\Python\Python313\Lib\site-packages\django\core\handlers\exception.py", line 55, in inner
    response = get_response(request)
  File "C:\Users\piyus\AppData\Local\Programs\Python\Python313\Lib\site-packages\django\core\handlers\base.py", line 197, in _get_response
    response = wrapped_callback(request, *callback_args, **callback_kwargs)
  File "C:\Users\piyus\AppData\Local\Programs\Python\Python313\Lib\site-packages\django\views\decorators\csrf.py", line 65, in _view_wrapper
    return view_func(request, *args, **kwargs)
  File "C:\Users\piyus\AppData\Local\Programs\Python\Python313\Lib\site-packages\django\views\generic\base.py", line 104, in view
    return self.dispatch(request, *args, **kwargs)
           ~~~~~~~~~~~~~^^^^^^^^^^^^^^^^^^^^^^^^^^
  File "C:\Users\piyus\AppData\Local\Programs\Python\Python313\Lib\site-packages\rest_framework\views.py", line 509, in dispatch
    response = self.handle_exception(exc)
  File "C:\Users\piyus\AppData\Local\Programs\Python\Python313\Lib\site-packages\rest_framework\views.py", line 469, in handle_exception
    self.raise_uncaught_exception(exc)
    ~~~~~~~~~~~~~~~~~~~~~~~~~~~~~^^^^^
  File "C:\Users\piyus\AppData\Local\Programs\Python\Python313\Lib\site-packages\rest_framework\views.py", line 480, in raise_uncaught_exception
    raise exc
  File "C:\Users\piyus\AppData\Local\Programs\Python\Python313\Lib\site-packages\rest_framework\views.py", line 506, in dispatch
    response = handler(request, *args, **kwargs)
  File "C:\Users\piyus\OneDrive\Desktop\final_noti\notification_project\notification_app\views.py", line 72, in get
    print(notifications[0].notification_type)
          ~~~~~~~~~~~~~^^^
  File "C:\Users\piyus\AppData\Local\Programs\Python\Python313\Lib\site-packages\django\db\models\query.py", line 452, in __getitem__
    return qs._result_cache[0]
           ~~~~~~~~~~~~~~~~^^^
IndexError: list index out of range
2024-12-18 11:38:51,503 - INFO - C:\Users\piyus\OneDrive\Desktop\final_noti\notification_project\notification_app\views.py changed, reloading.
2024-12-18 11:38:51,893 - INFO - C:\Users\piyus\OneDrive\Desktop\final_noti\notification_project\notification_app\views.py changed, reloading.
2024-12-18 11:39:03,716 - WARNING - Bad Request: /register/
2024-12-18 11:39:27,412 - WARNING - User with ID 2 not found. Notification not sent.
2024-12-18 11:39:36,422 - ERROR - Internal Server Error: /send_notification/
Traceback (most recent call last):
  File "C:\Users\piyus\AppData\Local\Programs\Python\Python313\Lib\site-packages\django\core\handlers\exception.py", line 55, in inner
    response = get_response(request)
  File "C:\Users\piyus\AppData\Local\Programs\Python\Python313\Lib\site-packages\django\core\handlers\base.py", line 220, in _get_response
    response = response.render()
  File "C:\Users\piyus\AppData\Local\Programs\Python\Python313\Lib\site-packages\django\template\response.py", line 114, in render
    self.content = self.rendered_content
                   ^^^^^^^^^^^^^^^^^^^^^
  File "C:\Users\piyus\AppData\Local\Programs\Python\Python313\Lib\site-packages\rest_framework\response.py", line 74, in rendered_content
    ret = renderer.render(self.data, accepted_media_type, context)
  File "C:\Users\piyus\AppData\Local\Programs\Python\Python313\Lib\site-packages\rest_framework\renderers.py", line 726, in render
    template = loader.get_template(self.template)
  File "C:\Users\piyus\AppData\Local\Programs\Python\Python313\Lib\site-packages\django\template\loader.py", line 19, in get_template
    raise TemplateDoesNotExist(template_name, chain=chain)
django.template.exceptions.TemplateDoesNotExist: rest_framework/api.html
2024-12-18 11:39:36,651 - WARNING - Not Found: /favicon.ico
2024-12-18 11:40:50,726 - ERROR - Internal Server Error: /send_notification/
Traceback (most recent call last):
  File "C:\Users\piyus\AppData\Local\Programs\Python\Python313\Lib\site-packages\django\core\handlers\exception.py", line 55, in inner
    response = get_response(request)
  File "C:\Users\piyus\AppData\Local\Programs\Python\Python313\Lib\site-packages\django\core\handlers\base.py", line 220, in _get_response
    response = response.render()
  File "C:\Users\piyus\AppData\Local\Programs\Python\Python313\Lib\site-packages\django\template\response.py", line 114, in render
    self.content = self.rendered_content
                   ^^^^^^^^^^^^^^^^^^^^^
  File "C:\Users\piyus\AppData\Local\Programs\Python\Python313\Lib\site-packages\rest_framework\response.py", line 74, in rendered_content
    ret = renderer.render(self.data, accepted_media_type, context)
  File "C:\Users\piyus\AppData\Local\Programs\Python\Python313\Lib\site-packages\rest_framework\renderers.py", line 726, in render
    template = loader.get_template(self.template)
  File "C:\Users\piyus\AppData\Local\Programs\Python\Python313\Lib\site-packages\django\template\loader.py", line 19, in get_template
    raise TemplateDoesNotExist(template_name, chain=chain)
django.template.exceptions.TemplateDoesNotExist: rest_framework/api.html
2024-12-18 11:42:44,724 - WARNING - User with ID 2 not found. Notification not sent.
2024-12-18 11:43:17,674 - WARNING - User with ID 2 not found. Notification not sent.
2024-12-18 11:43:39,332 - INFO - C:\Users\piyus\OneDrive\Desktop\final_noti\notification_project\notification_app\urls.py changed, reloading.
2024-12-18 11:43:39,403 - INFO - C:\Users\piyus\OneDrive\Desktop\final_noti\notification_project\notification_app\urls.py changed, reloading.
2024-12-18 11:43:44,600 - WARNING - User with ID 2 not found. Notification not sent.
2024-12-18 11:43:52,318 - INFO - C:\Users\piyus\OneDrive\Desktop\final_noti\notification_project\notification_app\urls.py changed, reloading.
2024-12-18 11:43:52,376 - INFO - C:\Users\piyus\OneDrive\Desktop\final_noti\notification_project\notification_app\urls.py changed, reloading.
2024-12-18 11:44:54,831 - WARNING - User with ID 2 not found. Notification not sent.
2024-12-18 11:45:10,557 - WARNING - Not Found: /notification/
2024-12-18 11:45:18,383 - WARNING - Unauthorized: /notifications/
2024-12-18 11:45:21,221 - WARNING - Unauthorized: /notifications/
2024-12-18 11:45:24,110 - WARNING - Unauthorized: /notifications/
2024-12-18 11:45:30,366 - WARNING - Not Found: /notifications
2024-12-18 11:45:38,758 - WARNING - Unauthorized: /notifications/
2024-12-18 11:50:17,868 - INFO - C:\Users\piyus\OneDrive\Desktop\final_noti\notification_project\notification_app\views.py changed, reloading.
2024-12-18 11:50:18,283 - INFO - C:\Users\piyus\OneDrive\Desktop\final_noti\notification_project\notification_app\views.py changed, reloading.
2024-12-18 11:50:35,859 - INFO - C:\Users\piyus\OneDrive\Desktop\final_noti\notification_project\notification_app\views.py changed, reloading.
2024-12-18 11:50:36,329 - INFO - C:\Users\piyus\OneDrive\Desktop\final_noti\notification_project\notification_app\views.py changed, reloading.
2024-12-18 11:50:43,264 - WARNING - User with ID 2 not found. Notification not sent.
2024-12-18 11:50:56,023 - INFO - C:\Users\piyus\OneDrive\Desktop\final_noti\notification_project\notification_app\views.py changed, reloading.
2024-12-18 11:50:56,365 - INFO - C:\Users\piyus\OneDrive\Desktop\final_noti\notification_project\notification_app\views.py changed, reloading.
2024-12-18 11:51:00,211 - WARNING - User with ID 2 not found. Notification not sent.
2024-12-18 11:51:21,628 - WARNING - User with ID 2 not found. Notification not sent.
2024-12-18 11:52:11,391 - INFO - C:\Users\piyus\OneDrive\Desktop\final_noti\notification_project\notification_app\views.py changed, reloading.
2024-12-18 11:52:14,396 - WARNING - User with ID 2 not found. Notification not sent.
2024-12-18 11:52:46,841 - INFO - C:\Users\piyus\OneDrive\Desktop\final_noti\notification_project\notification_app\views.py changed, reloading.
2024-12-18 11:52:49,932 - WARNING - User with ID 2 not found. Notification not sent.
2024-12-18 11:53:10,001 - INFO - C:\Users\piyus\OneDrive\Desktop\final_noti\notification_project\notification_app\views.py changed, reloading.
2024-12-18 11:53:12,863 - WARNING - User with ID 2 not found. Notification not sent.
2024-12-18 11:54:07,919 - INFO - C:\Users\piyus\OneDrive\Desktop\final_noti\notification_project\notification_app\views.py changed, reloading.
2024-12-18 11:54:09,870 - WARNING - User with ID 2 not found. Notification not sent.
2024-12-18 11:55:11,828 - INFO - C:\Users\piyus\OneDrive\Desktop\final_noti\notification_project\notification_app\views.py changed, reloading.
2024-12-18 11:55:16,462 - WARNING - User with ID 2 not found. Notification not sent.
2024-12-18 11:55:41,123 - INFO - C:\Users\piyus\OneDrive\Desktop\final_noti\notification_project\notification_app\views.py changed, reloading.
2024-12-18 11:55:43,798 - ERROR - Internal Server Error: /send_notification/
Traceback (most recent call last):
  File "C:\Users\piyus\AppData\Local\Programs\Python\Python313\Lib\site-packages\django\core\handlers\exception.py", line 55, in inner
    response = get_response(request)
  File "C:\Users\piyus\AppData\Local\Programs\Python\Python313\Lib\site-packages\django\core\handlers\base.py", line 197, in _get_response
    response = wrapped_callback(request, *callback_args, **callback_kwargs)
  File "C:\Users\piyus\AppData\Local\Programs\Python\Python313\Lib\site-packages\django\views\decorators\csrf.py", line 65, in _view_wrapper
    return view_func(request, *args, **kwargs)
  File "C:\Users\piyus\AppData\Local\Programs\Python\Python313\Lib\site-packages\django\views\generic\base.py", line 104, in view
    return self.dispatch(request, *args, **kwargs)
           ~~~~~~~~~~~~~^^^^^^^^^^^^^^^^^^^^^^^^^^
  File "C:\Users\piyus\AppData\Local\Programs\Python\Python313\Lib\site-packages\rest_framework\views.py", line 509, in dispatch
    response = self.handle_exception(exc)
  File "C:\Users\piyus\AppData\Local\Programs\Python\Python313\Lib\site-packages\rest_framework\views.py", line 469, in handle_exception
    self.raise_uncaught_exception(exc)
    ~~~~~~~~~~~~~~~~~~~~~~~~~~~~~^^^^^
  File "C:\Users\piyus\AppData\Local\Programs\Python\Python313\Lib\site-packages\rest_framework\views.py", line 480, in raise_uncaught_exception
    raise exc
  File "C:\Users\piyus\AppData\Local\Programs\Python\Python313\Lib\site-packages\rest_framework\views.py", line 506, in dispatch
    response = handler(request, *args, **kwargs)
  File "C:\Users\piyus\OneDrive\Desktop\final_noti\notification_project\notification_app\views.py", line 48, in post
    print(User.objects.all().user_id)
          ^^^^^^^^^^^^^^^^^^^^^^^^^^
AttributeError: 'QuerySet' object has no attribute 'user_id'
2024-12-18 11:56:04,329 - INFO - C:\Users\piyus\OneDrive\Desktop\final_noti\notification_project\notification_app\views.py changed, reloading.
2024-12-18 11:56:06,413 - WARNING - User with ID 2 not found. Notification not sent.
2024-12-18 11:56:19,418 - INFO - C:\Users\piyus\OneDrive\Desktop\final_noti\notification_project\notification_app\views.py changed, reloading.
2024-12-18 11:56:21,536 - WARNING - User with ID 2 not found. Notification not sent.
2024-12-18 12:03:32,645 - INFO - C:\Users\piyus\OneDrive\Desktop\final_noti\notification_project\notification_app\views.py changed, reloading.
2024-12-18 12:03:46,535 - WARNING - Method Not Allowed: /delete/
2024-12-18 12:03:50,140 - ERROR - Internal Server Error: /delete/
Traceback (most recent call last):
  File "C:\Users\piyus\AppData\Local\Programs\Python\Python313\Lib\site-packages\django\core\handlers\exception.py", line 55, in inner
    response = get_response(request)
  File "C:\Users\piyus\AppData\Local\Programs\Python\Python313\Lib\site-packages\django\core\handlers\base.py", line 197, in _get_response
    response = wrapped_callback(request, *callback_args, **callback_kwargs)
  File "C:\Users\piyus\AppData\Local\Programs\Python\Python313\Lib\site-packages\django\views\decorators\csrf.py", line 65, in _view_wrapper
    return view_func(request, *args, **kwargs)
  File "C:\Users\piyus\AppData\Local\Programs\Python\Python313\Lib\site-packages\django\views\generic\base.py", line 104, in view
    return self.dispatch(request, *args, **kwargs)
           ~~~~~~~~~~~~~^^^^^^^^^^^^^^^^^^^^^^^^^^
  File "C:\Users\piyus\AppData\Local\Programs\Python\Python313\Lib\site-packages\rest_framework\views.py", line 509, in dispatch
    response = self.handle_exception(exc)
  File "C:\Users\piyus\AppData\Local\Programs\Python\Python313\Lib\site-packages\rest_framework\views.py", line 469, in handle_exception
    self.raise_uncaught_exception(exc)
    ~~~~~~~~~~~~~~~~~~~~~~~~~~~~~^^^^^
  File "C:\Users\piyus\AppData\Local\Programs\Python\Python313\Lib\site-packages\rest_framework\views.py", line 480, in raise_uncaught_exception
    raise exc
  File "C:\Users\piyus\AppData\Local\Programs\Python\Python313\Lib\site-packages\rest_framework\views.py", line 506, in dispatch
    response = handler(request, *args, **kwargs)
  File "C:\Users\piyus\OneDrive\Desktop\final_noti\notification_project\notification_app\views.py", line 86, in delete
    with connection.cursor() as cursor:
         ^^^^^^^^^^
NameError: name 'connection' is not defined
2024-12-18 12:04:07,082 - INFO - C:\Users\piyus\OneDrive\Desktop\final_noti\notification_project\notification_app\views.py changed, reloading.
2024-12-18 12:04:12,767 - ERROR - Internal Server Error: /delete/
Traceback (most recent call last):
  File "C:\Users\piyus\AppData\Local\Programs\Python\Python313\Lib\site-packages\django\db\backends\utils.py", line 103, in _execute
    return self.cursor.execute(sql)
           ~~~~~~~~~~~~~~~~~~~^^^^^
  File "C:\Users\piyus\AppData\Local\Programs\Python\Python313\Lib\site-packages\django\db\backends\sqlite3\base.py", line 350, in execute
    return super().execute(query)
           ~~~~~~~~~~~~~~~^^^^^^^
sqlite3.OperationalError: near "SEQUENCE": syntax error

The above exception was the direct cause of the following exception:

Traceback (most recent call last):
  File "C:\Users\piyus\AppData\Local\Programs\Python\Python313\Lib\site-packages\django\core\handlers\exception.py", line 55, in inner
    response = get_response(request)
  File "C:\Users\piyus\AppData\Local\Programs\Python\Python313\Lib\site-packages\django\core\handlers\base.py", line 197, in _get_response
    response = wrapped_callback(request, *callback_args, **callback_kwargs)
  File "C:\Users\piyus\AppData\Local\Programs\Python\Python313\Lib\site-packages\django\views\decorators\csrf.py", line 65, in _view_wrapper
    return view_func(request, *args, **kwargs)
  File "C:\Users\piyus\AppData\Local\Programs\Python\Python313\Lib\site-packages\django\views\generic\base.py", line 104, in view
    return self.dispatch(request, *args, **kwargs)
           ~~~~~~~~~~~~~^^^^^^^^^^^^^^^^^^^^^^^^^^
  File "C:\Users\piyus\AppData\Local\Programs\Python\Python313\Lib\site-packages\rest_framework\views.py", line 509, in dispatch
    response = self.handle_exception(exc)
  File "C:\Users\piyus\AppData\Local\Programs\Python\Python313\Lib\site-packages\rest_framework\views.py", line 469, in handle_exception
    self.raise_uncaught_exception(exc)
    ~~~~~~~~~~~~~~~~~~~~~~~~~~~~~^^^^^
  File "C:\Users\piyus\AppData\Local\Programs\Python\Python313\Lib\site-packages\rest_framework\views.py", line 480, in raise_uncaught_exception
    raise exc
  File "C:\Users\piyus\AppData\Local\Programs\Python\Python313\Lib\site-packages\rest_framework\views.py", line 506, in dispatch
    response = handler(request, *args, **kwargs)
  File "C:\Users\piyus\OneDrive\Desktop\final_noti\notification_project\notification_app\views.py", line 89, in delete
    cursor.execute("ALTER SEQUENCE auth_user_id_seq RESTART WITH 1;")
    ~~~~~~~~~~~~~~^^^^^^^^^^^^^^^^^^^^^^^^^^^^^^^^^^^^^^^^^^^^^^^^^^^
  File "C:\Users\piyus\AppData\Local\Programs\Python\Python313\Lib\site-packages\django\db\backends\utils.py", line 122, in execute
    return super().execute(sql, params)
           ~~~~~~~~~~~~~~~^^^^^^^^^^^^^
  File "C:\Users\piyus\AppData\Local\Programs\Python\Python313\Lib\site-packages\django\db\backends\utils.py", line 79, in execute
    return self._execute_with_wrappers(
           ~~~~~~~~~~~~~~~~~~~~~~~~~~~^
        sql, params, many=False, executor=self._execute
        ^^^^^^^^^^^^^^^^^^^^^^^^^^^^^^^^^^^^^^^^^^^^^^^
    )
    ^
  File "C:\Users\piyus\AppData\Local\Programs\Python\Python313\Lib\site-packages\django\db\backends\utils.py", line 92, in _execute_with_wrappers
    return executor(sql, params, many, context)
  File "C:\Users\piyus\AppData\Local\Programs\Python\Python313\Lib\site-packages\django\db\backends\utils.py", line 100, in _execute
    with self.db.wrap_database_errors:
         ^^^^^^^^^^^^^^^^^^^^^^^^^^^^
  File "C:\Users\piyus\AppData\Local\Programs\Python\Python313\Lib\site-packages\django\db\utils.py", line 91, in __exit__
    raise dj_exc_value.with_traceback(traceback) from exc_value
  File "C:\Users\piyus\AppData\Local\Programs\Python\Python313\Lib\site-packages\django\db\backends\utils.py", line 103, in _execute
    return self.cursor.execute(sql)
           ~~~~~~~~~~~~~~~~~~~^^^^^
  File "C:\Users\piyus\AppData\Local\Programs\Python\Python313\Lib\site-packages\django\db\backends\sqlite3\base.py", line 350, in execute
    return super().execute(query)
           ~~~~~~~~~~~~~~~^^^^^^^
django.db.utils.OperationalError: near "SEQUENCE": syntax error
2024-12-18 12:04:27,296 - WARNING - Unauthorized: /notifications/
2024-12-18 12:05:15,353 - INFO - C:\Users\piyus\OneDrive\Desktop\final_noti\notification_project\notification_app\views.py changed, reloading.
2024-12-18 12:05:55,773 - INFO - C:\Users\piyus\OneDrive\Desktop\final_noti\notification_project\notification_app\urls.py changed, reloading.
2024-12-18 12:06:07,552 - INFO - C:\Users\piyus\OneDrive\Desktop\final_noti\notification_project\notification_app\urls.py changed, reloading.
2024-12-18 12:06:30,687 - WARNING - Unauthorized: /login/
2024-12-18 12:06:34,694 - WARNING - Unauthorized: /login/
2024-12-18 12:06:39,347 - WARNING - Unauthorized: /login/
2024-12-18 12:06:48,173 - WARNING - Unauthorized: /login/
2024-12-18 12:07:25,566 - INFO - Notification sent to user abcd2 (ID: 12): ascasdc
2024-12-18 12:07:32,145 - WARNING - Unauthorized: /login/
2024-12-18 12:10:43,485 - INFO - Notification sent to user 2 (ID: 14): ascasdc
2024-12-18 12:16:19,775 - INFO - Notification sent to user 1 (ID: 13): abc
2024-12-18 12:16:46,773 - INFO - Notification sent to user 2 (ID: 14): aa
2024-12-18 12:16:54,239 - INFO - Notification sent to user abcd2 (ID: 12): aa
2024-12-18 12:17:17,316 - ERROR - Internal Server Error: /register/
Traceback (most recent call last):
  File "C:\Users\piyus\AppData\Local\Programs\Python\Python313\Lib\site-packages\django\core\handlers\exception.py", line 55, in inner
    response = get_response(request)
  File "C:\Users\piyus\AppData\Local\Programs\Python\Python313\Lib\site-packages\django\core\handlers\base.py", line 220, in _get_response
    response = response.render()
  File "C:\Users\piyus\AppData\Local\Programs\Python\Python313\Lib\site-packages\django\template\response.py", line 114, in render
    self.content = self.rendered_content
                   ^^^^^^^^^^^^^^^^^^^^^
  File "C:\Users\piyus\AppData\Local\Programs\Python\Python313\Lib\site-packages\rest_framework\response.py", line 74, in rendered_content
    ret = renderer.render(self.data, accepted_media_type, context)
  File "C:\Users\piyus\AppData\Local\Programs\Python\Python313\Lib\site-packages\rest_framework\renderers.py", line 726, in render
    template = loader.get_template(self.template)
  File "C:\Users\piyus\AppData\Local\Programs\Python\Python313\Lib\site-packages\django\template\loader.py", line 19, in get_template
    raise TemplateDoesNotExist(template_name, chain=chain)
django.template.exceptions.TemplateDoesNotExist: rest_framework/api.html
2024-12-18 12:17:34,677 - INFO - Notification sent to user abc (ID: 16): aa
2024-12-18 12:19:44,981 - INFO - Notification sent to user qqq (ID: 18): aa
2024-12-18 12:20:15,782 - INFO - Notification sent to user qqq (ID: 18): sca
2024-12-18 12:21:58,437 - WARNING - Unauthorized: /login/
2024-12-18 12:22:38,200 - WARNING - Bad Request: /register/
2024-12-18 12:23:19,237 - INFO - Notification sent to user aaa (ID: 20): aaaaa
2024-12-18 14:35:34,630 - WARNING - Unauthorized: /login/
2024-12-18 14:41:07,571 - INFO - C:\Users\piyus\OneDrive\Desktop\final_noti\notification_project\notification_app\serializers.py changed, reloading.
2024-12-18 14:41:41,351 - INFO - C:\Users\piyus\OneDrive\Desktop\final_noti\notification_project\notification_app\views.py changed, reloading.
2024-12-18 14:41:52,096 - INFO - C:\Users\piyus\OneDrive\Desktop\final_noti\notification_project\notification_app\views.py changed, reloading.
2024-12-18 15:09:43,064 - INFO - C:\Users\piyus\OneDrive\Desktop\final_noti\notification_project\notification_app\urls.py changed, reloading.
2024-12-18 15:09:51,726 - INFO - C:\Users\piyus\OneDrive\Desktop\final_noti\notification_project\notification_app\views.py changed, reloading.
2024-12-18 19:49:53,832 - INFO - C:\Users\piyus\OneDrive\Desktop\final_noti\notification_project\notification_app\serializers.py changed, reloading.
2024-12-18 19:50:26,226 - WARNING - Unauthorized: /login/
2024-12-18 19:55:53,890 - INFO - C:\Users\piyus\OneDrive\Desktop\final_noti\notification_project\notification_project\settings.py changed, reloading.
2024-12-18 19:56:03,769 - INFO - C:\Users\piyus\OneDrive\Desktop\final_noti\notification_project\notification_project\settings.py changed, reloading.
2024-12-18 20:08:37,216 - INFO - Notification sent to user raj (ID: 25): emergency
2024-12-18 20:08:37,226 - INFO - Notification sent to user rohit (ID: 26): emergency
2024-12-18 20:09:06,105 - WARNING - Bad Request: /register/
2024-12-18 20:17:08,047 - INFO - Notification sent to user priya (ID: 31): emergency
2024-12-18 20:17:08,056 - INFO - Notification sent to user rijul (ID: 32): emergency
2024-12-18 20:17:34,888 - WARNING - Unauthorized: /login/
2024-12-18 20:18:53,434 - WARNING - Bad Request: /register/
2024-12-18 20:25:30,025 - WARNING - Bad Request: /register/
2024-12-18 20:32:37,904 - INFO - Notification sent to user harish (ID: 42): emergency
2024-12-18 20:32:37,909 - INFO - Notification sent to user arpan (ID: 43): emergency
2024-12-18 20:33:37,308 - WARNING - Unauthorized: /login/
